<?xml version="1.0"?>
<sdf version="1.4">
    <model name="simple_gripper">

        <static>false</static>

        <link name="fixed">
            <pose>0 0 .1 0 0 0</pose>
            <inertial>
                <pose>0 0 0 0 0 0</pose>
                <inertia>
                    <ixx>0.01</ixx>
                    <ixy>0</ixy>
                    <ixz>0</ixz>
                    <iyy>0.01</iyy>
                    <iyz>0</iyz>
                    <izz>0.01</izz>
                </inertia>
                <mass>0.5</mass>
            </inertial>
            <collision name="collision">
                <geometry>
                    <box>
                        <size>0.05 0.2 0.2</size>
                    </box>
                </geometry>
            </collision>
            <visual name="visual">
                <geometry>
                    <box>
                        <size>0.05 0.2 0.2</size>
                    </box>
                </geometry>
                <material>
                    <script>Gazebo/Purple</script>
                </material>
            </visual>
        </link>

<!--         <link name="connect">
            <pose>0.3 0.0 .25 0 1.5707 0</pose>
            <inertial>
                <inertia>
                    <ixx>0.01</ixx>
                    <ixy>0</ixy>
                    <ixz>0</ixz>
                    <iyy>0.01</iyy>
                    <iyz>0</iyz>
                    <izz>0.01</izz>
                </inertia>
                <mass>0.01</mass>
            </inertial>
            <collision name="collision">
                <geometry>
                    <cylinder>
                      <radius>.01</radius>
                      <length>.6</length>
                    </cylinder>
                </geometry>
            </collision>
            <visual name="visual">
                <geometry>
                    <cylinder>
                      <radius>.01</radius>
                      <length>.6</length>
                    </cylinder>
                </geometry>
                <material>
                    <script>Gazebo/Red</script>
                </material>
            </visual>
        </link> -->

        <link name="mover">
            <pose>0.06 0.0 .1 0 0 0</pose>
            <inertial>
                <inertia>
                    <ixx>0.01</ixx>
                    <ixy>0</ixy>
                    <ixz>0</ixz>
                    <iyy>0.01</iyy>
                    <iyz>0</iyz>
                    <izz>0.01</izz>
                </inertia>
                <mass>0.05</mass>
            </inertial>
            <collision name="collision">
                <geometry>
                    <box>
                        <size>0.05 0.2 0.2</size>
                    </box>
                </geometry>
            </collision>
            <visual name="visual">
                <geometry>
                    <box>
                        <size>0.05 0.2 0.2</size>
                    </box>
                </geometry>
                <material>
                    <script>Gazebo/Purple</script>
                </material>
            </visual>
        </link>

        <joint name="grip" type="prismatic">
            <child>mover</child>
            <parent>fixed</parent>
            <axis>
                <limit>
                    <lower>0</lower>
                    <upper>.6</upper>
                </limit>
                <xyz>1 0 0</xyz>
            </axis>
        </joint>
    </model>
</sdf>
