<?xml version="1.0"?>
<robot xmlns:xacro="http://ros.org/wiki/xacro" name="wheels">
  <xacro:include filename="$(find mil_gazebo)/xacro/util.xacro"/>

  <xacro:property name="front_wheel_radius" value="0.127"/>
  <xacro:property name="front_wheel_width" value="0.127"/>
  <xacro:property name="front_wheel_mass" value="3"/>
  
  <xacro:property name="back_wheel_radius" value="0.1335"/>
  <xacro:property name="back_wheel_width" value="0.203"/>
  <xacro:property name="back_wheel_mass" value="5"/>

  <xacro:macro name="front_wheel_geometry">	  
    <geometry>
       <cylinder length="${front_wheel_width}" radius="${front_wheel_radius}"/>
    </geometry>
  </xacro:macro>

  <xacro:macro name="back_wheel_geometry">
    <geometry>
       <cylinder length="${back_wheel_width}" radius="${back_wheel_radius}"/>
    </geometry>
  </xacro:macro>

  <xacro:macro name="do_wheel_surface" params="name">
    <gazebo reference="${name}_link">
      <mu1>500</mu1> <!-- friction parallel to the tire (wheels need friction to roll) -->
    </gazebo>
  </xacro:macro>
  
  <xacro:macro name="front_wheel_origin">
     <origin rpy="0 1.5708 0"/>
  </xacro:macro>

  <xacro:macro name="back_wheel_origin">
     <origin rpy="0 1.5708 1.5708"/>
  </xacro:macro>

  <xacro:macro name="front_wheel_physical">
    <inertial>
      <xacro:front_wheel_origin/>
      <mass value="${front_wheel_mass}"/>
      <xacro:cylinder_inertia h="${front_wheel_width}" r="${front_wheel_radius}" mass="${front_wheel_mass}"/>
    </inertial>
    <collision>
      <xacro:front_wheel_origin/>
      <xacro:front_wheel_geometry/>
    </collision>
    <visual>
      <xacro:front_wheel_origin/>
      <xacro:front_wheel_geometry/>
    </visual>
  </xacro:macro>

  <xacro:macro name="back_wheel_physical">
    <inertial>
      <xacro:back_wheel_origin/>
      <mass value="${back_wheel_mass}"/>
      <xacro:cylinder_inertia h="${back_wheel_width}" r="${back_wheel_radius}" mass="${back_wheel_mass}"/>
    </inertial>
    <collision>
      <xacro:back_wheel_origin/>
      <xacro:back_wheel_geometry/>
    </collision>
    <visual>
      <xacro:back_wheel_origin/>
      <xacro:back_wheel_geometry/>
    </visual>
  </xacro:macro>

  <!--Front Wheel Xacro-->
  <xacro:macro name="front_wheel" params="name xyz parent_link:='base_link'">
    <link name="${name}_link">
       <xacro:front_wheel_physical/>
    </link>

    <joint name="${parent_link}_to_${name}_link_joint" type="continuous">
      <parent link="${parent_link}" />
      <child link="${name}_link" />
      <origin xyz="${xyz}" rpy="0 0 0"/>
      <axis xyz="1 0 0"/>
    </joint>

    <xacro:do_wheel_surface name="${name}"/>
    <xacro:joint_transmission name="${name}" parent_link="${parent_link}"/>
  </xacro:macro>

  <!--Back Wheel Xacro-->
  <xacro:macro name="back_wheel" params="name xyz parent_link:='base_link'">
    <link name="${name}_link">
       <xacro:back_wheel_physical/>
    </link>

    <joint name="${parent_link}_to_${name}_link_joint" type="fixed">
      <parent link="${parent_link}" />
      <child link="${name}_link" />
      <origin xyz="${xyz}" rpy="0 0 0"/>
    </joint>

    <xacro:do_wheel_surface name="${name}"/>
  </xacro:macro>
</robot>
